<?xml version="1.0" ?>
<robot name="simple_robot"  xmlns:xacro="http://www.ros.org/wiki/xacro">

<material name="black">
  <color rgba="0 0 0 1"></color>
</material>

<material name="yellow">
   <color rgba="1.0 1.0 0 1"></color>
</material>

<material name="white">
   <color rgba="1 1 1 1"></color>
</material>

  <link name="link_chassis">
    <pose> 0 0 0.3 0 0 0 </pose>

    <inertial>
      <mass value = "5"/>
      <origin rpy ="0 0 0" xyz ="0 0 0.3"/>
      <inertia ixx="0.0395" ixy="0" ixz="0" iyy="0.106" iyz="0" izz="0.106"/>
    </inertial>

    <visual>
      <origin rpy="0 0 0" xyz="0 0 0.3"/>
      <geometry>
        <box size="2 1.2 0.3"/>
      </geometry>
      <material name="yellow" />
    </visual>
  </link>


    <link name="left_front_shaft">
        <visual>
            <origin xyz="0.7 0.7 0" rpy="1.57 0 0"></origin>
            <geometry>
                <cylinder length="0.3" radius="0.1" />
            </geometry>
            <material name="white"/>
        </visual>
    </link>

          <joint name="LF_shaft_joint" type="fixed">
            <origin xyz="0 0 0.3" rpy="0 0 0"></origin>
            <parent link="link_chassis" />
            <child link="left_front_shaft"/>
        </joint>


    <link name="left_front_wheel">
        <visual>
            <origin xyz="0 0 0" rpy="1.57 0 0"></origin>
            <geometry>
                <cylinder length="0.2" radius="0.3" />
            </geometry>
            <material name="black"/>
        </visual>
    </link>

          <joint name="LF_wheel_joint" type="continuous">
            <origin xyz="0.7 0.72 0" rpy="0 0 0"></origin>
            <parent link="left_front_shaft" />
            <child link="left_front_wheel"/>
            <axis xyz="0 1 0" />
        </joint>



    <link name="right_front_shaft">
        <visual>
            <origin xyz="0.7 -0.7 0" rpy="1.57 0 0"></origin>
            <geometry>
                <cylinder length="0.3" radius="0.1" />
            </geometry>
            <material name="white"/>
        </visual>
    </link>

          <joint name="RF_shaft_joint" type="fixed">
            <origin xyz="0 0 0.3" rpy="0 0 0"></origin>
            <parent link="link_chassis" />
            <child link="right_front_shaft"/>
        </joint>


    <link name="right_front_wheel">
        <visual>
            <origin xyz="0 0 0" rpy="1.57 0 0"></origin>
            <geometry>
                <cylinder length="0.2" radius="0.3" />
            </geometry>
            <material name="black"/>
        </visual>
    </link>

          <joint name="RF_wheel_joint" type="continuous">
            <origin xyz="0.7 -0.72 0" rpy="0 0 0"></origin>
            <parent link="right_front_shaft" />
            <child link="right_front_wheel"/>
            <axis xyz="0 1 0" />
        </joint>





   <link name="left_back_shaft">
        <visual>
            <origin xyz="-0.7 0.7 0" rpy="1.57 0 0"></origin>
            <geometry>
                <cylinder length="0.3" radius="0.1" />
            </geometry>
            <material name="white"/>
        </visual>
    </link>

          <joint name="LB_shaft_joint" type="fixed">
            <origin xyz="0 0 0.3" rpy="0 0 0"></origin>
            <parent link="link_chassis" />
            <child link="left_back_shaft"/>
        </joint>


    <link name="left_back_wheel">
        <visual>
            <origin xyz="0 0 0" rpy="1.57 0 0"></origin>
            <geometry>
                <cylinder length="0.2" radius="0.3" />
            </geometry>
            <material name="black"/>
        </visual>
    </link>

          <joint name="LB_wheel_joint" type="continuous">
            <origin xyz="-0.7 0.72 0" rpy="0 0 0"></origin>
            <parent link="left_back_shaft" />
            <child link="left_back_wheel"/>
            <axis xyz="0 1 0" />
        </joint>



    <link name="right_back_shaft">
        <visual>
            <origin xyz="-0.7 -0.7 0" rpy="1.57 0 0"></origin>
            <geometry>
                <cylinder length="0.3" radius="0.1" />
            </geometry>
            <material name="white"/>
        </visual>
    </link>

          <joint name="RB_shaft_joint" type="fixed">
            <origin xyz="0 0 0.3" rpy="0 0 0"></origin>
            <parent link="link_chassis" />
            <child link="right_back_shaft"/>
        </joint>


    <link name="right_back_wheel">
        <visual>
            <origin xyz="0 0 0" rpy="1.57 0 0"></origin>
            <geometry>
                <cylinder length="0.2" radius="0.3" />
            </geometry>
            <material name="black"/>
        </visual>
    </link>

          <joint name="RB_wheel_joint" type="continuous">
            <origin xyz="-0.7 -0.72 0" rpy="0 0 0"></origin>
            <parent link="right_back_shaft" />
            <child link="right_back_wheel"/>
            <axis xyz="0 1 0" />
        </joint>

</robot>
